Workbook
Name Country: '[1]Country Code'!$B$2:$B$275
Name Country: '[2]Country Code'!$B$2:$B$275
Name country_name: '[3]Arrears (2)'!$D$5:$D$137
Name data: '[3]Arrears (3)'!$F$5:$AX$137
Name Interest_Data: [4]Data!$H$6:$AT$141
Name Interest_GEO: [4]Data!$G$6:$G$141
Name Principal_Data: [4]Data!$H$143:$AT$278
Name Principal_GEO: [4]Data!$G$143:$G$278
Name year: '[3]Arrears (3)'!$F$3:$AX$3
Name Years: [4]Data!$H$3:$AT$3

Sheet 2021 Update
D1: 1960 | E1: 1961 | F1: 1962 | G1: 1963 | H1: 1964 | I1: 1965 | J1: 1966 | K1: 1967 | L1: 1968 | M1: 1969 | N1: 1970 | O1: 1971 | P1: 1972 | Q1: 1973 | R1: 1974 | S1: 1975 | T1: 1976 | U1: 1977 | V1: 1978 | W1: 1979 | X1: 1980 | Y1: 1981 | Z1: 1982 | AA1: 1983 | AB1: 1984 | AC1: 1985 | AD1: 1986 | AE1: 1987 | AF1: 1988 | AG1: 1989 | AH1: 1990 | AI1: 1991 | AJ1: 1992 | AK1: 1993 | AL1: 1994 | AM1: 1995 | AN1: 1996 | AO1: 1997 | AP1: 1998 | AQ1: 1999 | AR1: 2000 | AS1: 2001 | AT1: 2002 | AU1: 2003 | AV1: 2004 | AW1: 2005 | AX1: 2006 | AY1: 2007 | AZ1: 2008 | BA1: 2009 | BB1: 2010 | BC1: 2011 | BD1: 2012 | BE1: 2013 | BF1: 2014 | BG1: 2015 | BH1: 2016 | BI1: 2017 | BJ1: 2018 | BK1: 2019 | BL1: 2020
A2: Database of Sovereign Defaults
A3: Last Update: 08 August 2021
A5: A. Summary Data
A7: Total Debt in Default (US$ mil) by Creditor | D7: 1939.2725 | E7: 3366.897 | F7: 2249.199 | G7: 2108.721 | H7: 3417.533 | I7: 4368.5133 | J7: 2887.0433 | K7: 1851.0025 | L7: 2282.797 | M7: 2094.6905 | N7: 5300.8 | O7: 1199.9573 | P7: 2325.5401 | Q7: 2112.0456 | R7: 3101.9258 | S7: 3302.7902 | T7: 4563.8312 | U7: 10394.387 | V7: 10451.803 | W7: 14525.593 | X7: 11762.299 | Y7: 16414.421 | Z7: 50723.996 | AA7: 110510.34 | AB7: 117361.11 | AC7: 165924.17 | AD7: 246760.85 | AE7: 361336.32 | AF7: 299117.66 | AG7: 356341.13 | AH7: 449573.43 | AI7: 323601.88 | AJ7: 264499.51 | AK7: 315711.56 | AL7: 321413.55 | AM7: 240339.38 | AN7: 261244.19 | AO7: 217894.61 | AP7: 249949.77 | AQ7: 325096.08 | AR7: 261790.37 | AS7: 232672.91 | AT7: 364304.46 | AU7: 379074.39 | AV7: 384857.35 | AW7: 388102.3 | AX7: 257365.36 | AY7: 206220.1 | AZ7: 214644.81 | BA7: 199407.3 | BB7: 209332.8 | BC7: 174147.65 | BD7: 505628.88 | BE7: 526235.69 | BF7: 241500.01 | BG7: 210332.08 | BH7: 253347.94 | BI7: 236268.08 | BJ7: 394269.6 | BK7: 299555.83 | BL7: 443242.81
A8: - IMF | D8: 173 | E8: 53 | F8: 54 | G8: 25.3 | H8: 211 | I8: 188.6 | J8: 114.65 | K8: 40.15 | L8: 16.8 | M8: 3.5 | N8: 0 | O8: 0 | P8: 0 | Q8: 0 | R8: 0 | S8: 15 | T8: 16 | U8: 16 | V8: 85.490921 | W8: 175.26602 | X8: 248.45283 | Y8: 75.360296 | Z8: 115.14141 | AA8: 79.12874 | AB8: 996.90662 | AC8: 3521.1307 | AD8: 5922.9755 | AE8: 5978.3103 | AF8: 6395.0567 | AG8: 6531.8118 | AH8: 6534.8799 | AI8: 6692.8647 | AJ8: 7343.2905 | AK8: 7704.0844 | AL8: 6583.8043 | AM8: 6751.4977 | AN8: 4536.2568 | AO8: 4420.5106 | AP8: 4764.2303 | AQ8: 4803.5749 | AR8: 4751.7214 | AS8: 4659.9129 | AT8: 5160.4344 | AU8: 7912.9579 | AV8: 5154.4813 | AW8: 4734.6625 | AX8: 5250.1633 | AY8: 5692.2667 | AZ8: 5687.0785 | BA8: 4504.0487 | BB8: 4472.028 | BC8: 4510.2778 | BD8: 4550.4051 | BE8: 4599.2703 | BF8: 4361.7412 | BG8: 6428.4168 | BH8: 4114.2037 | BI8: 4238.0298 | BJ8: 4218.77 | BK8: 4267.5 | BL8: 4488
A9: - IBRD | D9: 0 | E9: 0 | F9: 0 | G9: 0 | H9: 0 | I9: 0 | J9: 0 | K9: 30 | L9: 1 | M9: 0 | N9: 0 | O9: 0 | P9: 0 | Q9: 0 | R9: 0 | S9: 0 | T9: 0.3 | U9: 0 | V9: 0 | W9: 0 | X9: 0 | Y9: 0 | Z9: 0 | AA9: 0 | AB9: 0 | AC9: 24 | AD9: 48 | AE9: 250 | AF9: 697 | AG9: 624 | AH9: 1751 | AI9: 1775 | AJ9: 1995.65 | AK9: 1281 | AL9: 1637 | AM9: 2275 | AN9: 2656 | AO9: 2786 | AP9: 2647 | AQ9: 2839 | AR9: 2931 | AS9: 2354 | AT9: 1487 | AU9: 1426 | AV9: 121 | AW9: 880 | AX9: 1019 | AY9: 1186 | AZ9: 795 | BA9: 565 | BB9: 631 | BC9: 701 | BD9: 761 | BE9: 888 | BF9: 852 | BG9: 873 | BH9: 896 | BI9: 919 | BJ9: 954 | BK9: 988 | BL9: 1015
A10: - IDA | D10: 0 | E10: 0 | F10: 0 | G10: 0 | H10: 0 | I10: 0 | J10: 0 | K10: 0 | L10: 0 | M10: 0 | N10: 0 | O10: 0 | P10: 0 | Q10: 0 | R10: 0 | S10: 0 | T10: 0 | U10: 0 | V10: 0 | W10: 0 | X10: 0 | Y10: 1 | Z10: 1 | AA10: 1 | AB10: 2 | AC10: 0 | AD10: 0 | AE10: 0 | AF10: 12 | AG10: 8.372 | AH10: 29 | AI10: 18 | AJ10: 24 | AK10: 39 | AL10: 88 | AM10: 131 | AN10: 181 | AO10: 238 | AP10: 287 | AQ10: 379 | AR10: 469 | AS10: 547 | AT10: 694 | AU10: 597 | AV10: 751 | AW10: 877 | AX10: 1053 | AY10: 1213 | AZ10: 1066 | BA10: 1149 | BB10: 1265 | BC10: 1414 | BD10: 1496 | BE10: 1203 | BF10: 1337 | BG10: 1356 | BH10: 1452 | BI10: 1547 | BJ10: 1665 | BK10: 1758 | BL10: 1848
A11: - Paris Club | D11: 0 | E11: 300 | F11: 270 | G11: 0 | H11: 270 | I11: 297 | J11: 480 | K11: 110 | L11: 484 | M11: 859 | N11: 2112 | O11: 0 | P11: 499 | Q11: 239 | R11: 1304 | S11: 230 | T11: 280 | U11: 260 | V11: 3005 | W11: 3183 | X11: 3700 | Y11: 3664 | Z11: 964 | AA11: 9771 | AB11: 4005 | AC11: 17251 | AD11: 22955 | AE11: 34513.2 | AF11: 18544 | AG11: 27100 | AH11: 25164.8 | AI11: 75066.8 | AJ11: 29060.2 | AK11: 29097.3 | AL11: 35910 | AM11: 47418 | AN11: 79868 | AO11: 23787.7 | AP11: 27404.4 | AQ11: 34999.2 | AR11: 49139.7 | AS11: 68601.6 | AT11: 66727.6 | AU11: 51002.9 | AV11: 101443.1 | AW11: 85121 | AX11: 53009.1 | AY11: 44226 | AZ11: 57362.3 | BA11: 48924.3 | BB11: 53685.3 | BC11: 48027.3 | BD11: 63776.3 | BE11: 44463.3 | BF11: 43938.3 | BG11: 36349.3 | BH11: 36448.2 | BI11: 28091.14 | BJ11: 34883.3 | BK11: 40655.4 | BL11: 44654.917
A12: - China | AR12: 5 | AS12: 580.4 | AT12: 937.5 | AU12: 399.75 | AV12: 51.9 | AW12: 161.5 | AX12: 318.7 | AY12: 1853.2 | AZ12: 69.2 | BA12: 3 | BB12: 9890.9 | BC12: 6264 | BD12: 507 | BE12: 131 | BF12: 1672.7386 | BG12: 43 | BH12: 25243 | BI12: 4783.83 | BJ12: 23109.1 | BK12: 18295.5 | BL12: 22365.365
A13: - Other official creditors | D13: 79.8 | E13: 610.2 | F13: 150.3 | G13: 163.8 | H13: 678.8 | I13: 1690.9 | J13: 997.6 | K13: 126.3 | L13: 743.1 | M13: 333 | N13: 1488.3811 | O13: 197.45555 | P13: 628.63415 | Q13: 691.40032 | R13: 685.59878 | S13: 1444.3304 | T13: 2060.4745 | U13: 9023.5522 | V13: 2685.723 | W13: 3167.7774 | X13: 3723.7618 | Y13: 5452.0248 | Z13: 7177.8301 | AA13: 8362.3397 | AB13: 11332.663 | AC13: 16720.047 | AD13: 28512.303 | AE13: 24646.309 | AF13: 35942.365 | AG13: 68217.25 | AH13: 58854.672 | AI13: 52366.121 | AJ13: 52919.068 | AK13: 65795.473 | AL13: 110712.85 | AM13: 76981.776 | AN13: 76073.844 | AO13: 96863.213 | AP13: 99648.921 | AQ13: 117134.93 | AR13: 119709.16 | AS13: 71732.682 | AT13: 146897.62 | AU13: 158433 | AV13: 117740.51 | AW13: 146663.31 | AX13: 124103.63 | AY13: 93323.617 | AZ13: 88817.778 | BA13: 81495.795 | BB13: 88030.089 | BC13: 76400.488 | BD13: 76894.62 | BE13: 432386.13 | BF13: 113209.9 | BG13: 82540.103 | BH13: 85198.581 | BI13: 93246.171 | BJ13: 201565.75 | BK13: 90607.906 | BL13: 102031.62
A14: - FC bank loans | D14: 1 | E14: 363.5 | F14: 15 | G14: 50 | H14: 106 | I14: 130.9 | J14: 24 | K14: 27 | L14: 104 | M14: 19 | N14: 636.7 | O14: 0 | P14: 160 | Q14: 30 | R14: 0 | S14: 0 | T14: 1357 | U14: 0 | V14: 2481 | W14: 5101 | X14: 2088 | Y14: 4906.677 | Z14: 36070.5 | AA14: 84034.222 | AB14: 83966.779 | AC14: 120229.71 | AD14: 148729 | AE14: 223151.16 | AF14: 218797.44 | AG14: 230760.04 | AH14: 264115.65 | AI14: 147940.42 | AJ14: 149550.31 | AK14: 177428.32 | AL14: 140851.65 | AM14: 85418.056 | AN14: 77310.575 | AO14: 72931.334 | AP14: 32355.216 | AQ14: 25417.571 | AR14: 25671.567 | AS14: 26203.61 | AT14: 30528.447 | AU14: 32058.155 | AV14: 33409.469 | AW14: 30049.152 | AX14: 32362.477 | AY14: 17796.894 | AZ14: 16650.2 | BA14: 17678.936 | BB14: 18562.798 | BC14: 18214.653 | BD14: 18638.767 | BE14: 15344.653 | BF14: 14832.869 | BG14: 14993.653 | BH14: 13877.842 | BI14: 15382.833 | BJ14: 16718.306 | BK14: 14933.48 | BL14: 15206.562
A15: - FC bonds | D15: 1349.4725 | E15: 1407.387 | F15: 1387.089 | G15: 1325.811 | H15: 1356.923 | I15: 1572.3033 | J15: 1270.7933 | K15: 1227.5525 | L15: 858.89697 | M15: 879.19049 | N15: 817.95937 | O15: 857.74494 | P15: 845.09011 | Q15: 859.21325 | R15: 878.26737 | S15: 842.10772 | T15: 333.83855 | U15: 303.336 | V15: 330.7626 | W15: 369.79381 | X15: 374.84082 | Y15: 775.9307 | Z15: 663.52068 | AA15: 618.68545 | AB15: 660.88179 | AC15: 662.02948 | AD15: 302.22942 | AE15: 5499.1958 | AF15: 5792.6 | AG15: 2219.8 | AH15: 483 | AI15: 578.65432 | AJ15: 2230.3913 | AK15: 1636.9195 | AL15: 1000.0201 | AM15: 131.13624 | AN15: 125.53995 | AO15: 82.060765 | AP15: 29872.001 | AQ15: 39856.934 | AR15: 44976.572 | AS15: 44684.467 | AT15: 97585.789 | AU15: 105379.41 | AV15: 103532.77 | AW15: 107685.12 | AX15: 29616.057 | AY15: 32464.696 | AZ15: 35747.845 | BA15: 36631.764 | BB15: 15818.305 | BC15: 13956.179 | BD15: 327570.9 | BE15: 15253.146 | BF15: 46554.26 | BG15: 64741.379 | BH15: 74589.081 | BI15: 75277.451 | BJ15: 88023.41 | BK15: 102496.71 | BL15: 224737.68
A16: - Other private creditors | D16: 225 | E16: 306.81 | F16: 248.81 | G16: 413.81 | H16: 272.81 | I16: 341.81 | J16: 0 | K16: 0 | L16: 75 | M16: 1 | N16: 133.75961 | O16: 144.75685 | P16: 192.81581 | Q16: 292.43199 | R16: 234.05966 | S16: 311.35206 | T16: 360.21817 | U16: 789.49837 | V16: 1393.8268 | W16: 1470.7554 | X16: 1298.2433 | Y16: 1500.9256 | Z16: 2913.9575 | AA16: 3173.8114 | AB16: 5490.0446 | AC16: 6755.0392 | AD16: 8395.1258 | AE16: 11952.939 | AF16: 12598.194 | AG16: 17774.854 | AH16: 27069.428 | AI16: 29698.02 | AJ16: 21126.599 | AK16: 25756.467 | AL16: 24626.22 | AM16: 21100.913 | AN16: 20350.979 | AO16: 16691.79 | AP16: 15930.998 | AQ16: 14975.864 | AR16: 13992.64 | AS16: 11480.242 | AT16: 10334.064 | AU16: 11312.215 | AV16: 12125.123 | AW16: 10631.559 | AX16: 10080.232 | AY16: 8089.4215 | AZ16: 8115.4073 | BA16: 8011.4571 | BB16: 10145.377 | BC16: 4547.7544 | BD16: 11334.882 | BE16: 3716.1945 | BF16: 14239.199 | BG16: 3004.2292 | BH16: 11271.031 | BI16: 12779.625 | BJ16: 17179.962 | BK16: 21371.335 | BL16: 21821.663
A17: - LC debt | D17: 111 | E17: 326 | F17: 124 | G17: 130 | H17: 522 | I17: 147 | J17: 0 | K17: 290 | L17: 0 | M17: 0 | N17: 112 | O17: 0 | P17: 0 | Q17: 0 | R17: 0 | S17: 460 | T17: 156 | U17: 2 | V17: 470 | W17: 1058 | X17: 329 | Y17: 38.50237 | Z17: 2818.0458 | AA17: 4470.1558 | AB17: 10906.831 | AC17: 761.21131 | AD17: 31896.211 | AE17: 55345.211 | AF17: 339 | AG17: 3105 | AH17: 65571 | AI17: 9466 | AJ17: 250 | AK17: 6973 | AL17: 4 | AM17: 132 | AN17: 142 | AO17: 94 | AP17: 37040 | AQ17: 84690 | AR17: 144 | AS17: 1829 | AT17: 3952 | AU17: 10553 | AV17: 10528 | AW17: 1299 | AX17: 553 | AY17: 375 | AZ17: 334 | BA17: 444 | BB17: 6832 | BC17: 112 | BD17: 99 | BE17: 8251 | BF17: 502 | BG17: 3 | BH17: 258 | BI17: 3 | BJ17: 5952 | BK17: 4182 | BL17: 5074
A19: Identified domestic arrears | AW19: 4393.1216 | AX19: 4381.0383 | AY19: 7186.2114 | AZ19: 15208.919 | BA19: 18297.853 | BB19: 13293.276 | BC19: 12757.182 | BD19: 12220.196 | BE19: 12204.051 | BF19: 18775.367 | BG19: 25260.774 | BH19: 32500.677 | BI19: 46026.576 | BJ19: 143570.62 | BK19: 157078.15 | BL19: 152866
A21: Total Debt in Default (US$ mil) by Debtor | D21: 1939.2725 | E21: 3366.897 | F21: 2249.199 | G21: 2108.721 | H21: 3417.533 | I21: 4368.5133 | J21: 2887.0433 | K21: 1851.0025 | L21: 2282.797 | M21: 2094.6905 | N21: 5300.8 | O21: 1199.9573 | P21: 2325.5401 | Q21: 2112.0456 | R21: 3101.9258 | S21: 3302.7902 | T21: 4563.8312 | U21: 10394.387 | V21: 10451.803 | W21: 14525.593 | X21: 11762.299 | Y21: 16414.421 | Z21: 50723.996 | AA21: 110510.34 | AB21: 117361.11 | AC21: 165924.17 | AD21: 246760.85 | AE21: 361336.32 | AF21: 299117.66 | AG21: 356341.13 | AH21: 449573.43 | AI21: 323601.88 | AJ21: 264499.51 | AK21: 315711.56 | AL21: 321413.55 | AM21: 240339.38 | AN21: 261244.19 | AO21: 217894.61 | AP21: 249949.77 | AQ21: 325096.08 | AR21: 261790.37 | AS21: 232672.91 | AT21: 364304.46 | AU21: 379074.39 | AV21: 384857.35 | AW21: 388102.3 | AX21: 257365.36 | AY21: 206220.1 | AZ21: 214644.81 | BA21: 199407.3 | BB21: 209332.8 | BC21: 174147.65 | BD21: 505628.88 | BE21: 526235.69 | BF21: 241500.01 | BG21: 210332.08 | BH21: 253347.94 | BI21: 236268.08 | BJ21: 394269.6 | BK21: 299555.83 | BL21: 443242.81
A22: - Advanced economies | D22: 368.6016 | E22: 377.7548 | F22: 386.908 | G22: 301.0812 | H22: 307.6444 | I22: 314.2076 | J22: 0 | K22: 0 | L22: 0 | M22: 0 | N22: 0 | O22: 0 | P22: 0 | Q22: 0 | R22: 0 | S22: 0 | T22: 0 | U22: 0 | V22: 0 | W22: 0 | X22: 0 | Y22: 0 | Z22: 0 | AA22: 0 | AB22: 0 | AC22: 0 | AD22: 0 | AE22: 0 | AF22: 0 | AG22: 0 | AH22: 0 | AI22: 0 | AJ22: 0 | AK22: 0 | AL22: 0 | AM22: 0 | AN22: 0 | AO22: 0 | AP22: 0 | AQ22: 0 | AR22: 0 | AS22: 0 | AT22: 0 | AU22: 0 | AV22: 0 | AW22: 0 | AX22: 0 | AY22: 0 | AZ22: 0 | BA22: 0 | BB22: 0 | BC22: 0 | BD22: 312420 | BE22: 355519.24 | BF22: 0 | BG22: 3325 | BH22: 25904 | BI22: 46602 | BJ22: 160889 | BK22: 53300 | BL22: 56649
A23: - Emerging/frontier markets | D23: 802.26342 | E23: 1957.0106 | F23: 1089.4578 | G23: 855.80502 | H23: 1556.6522 | I23: 2261.3994 | J23: 1832.8466 | K23: 1378.8096 | L23: 1778.7252 | M23: 1901.3312 | N23: 5103.8641 | O23: 1005.6962 | P23: 1948.4586 | Q23: 1599.0875 | R23: 2337.3986 | S23: 2118.6881 | T23: 2269.9905 | U23: 7833.142 | V23: 5855.8979 | W23: 6927.8414 | X23: 5105.1173 | Y23: 9743.5088 | Z23: 40009.367 | AA23: 96800.328 | AB23: 100760.51 | AC23: 140043.27 | AD23: 212848.47 | AE23: 318029.14 | AF23: 247219.96 | AG23: 290978.5 | AH23: 381340.67 | AI23: 247349.17 | AJ23: 189388.67 | AK23: 234545.32 | AL23: 218727.6 | AM23: 115593.5 | AN23: 149493.1 | AO23: 113515.46 | AP23: 145940.2 | AQ23: 233604.5 | AR23: 170808.06 | AS23: 134274.81 | AT23: 263908 | AU23: 278664.51 | AV23: 273458.65 | AW23: 270286.27 | AX23: 151037.9 | AY23: 110147.28 | AZ23: 99716.075 | BA23: 95673.085 | BB23: 86610.31 | BC23: 59552.099 | BD23: 67587.755 | BE23: 68495.041 | BF23: 111974.57 | BG23: 109749.07 | BH23: 121389.12 | BI23: 88312.831 | BJ23: 122076.47 | BK23: 137032.82 | BL23: 264485.29
A24: - HIPC countries | D24: 454.347 | E24: 491.8 | F24: 488.2305 | G24: 659.961 | H24: 855.0915 | I24: 1005.022 | J24: 562.555 | K24: 156.298 | L24: 459.891 | M24: 161.834 | N24: 92.152326 | O24: 121.41453 | P24: 306.17158 | Q24: 440.96369 | R24: 672.22876 | S24: 738.90142 | T24: 1761.0254 | U24: 1977.0526 | V24: 3889.8862 | W24: 6201.8154 | X24: 5620.7477 | Y24: 5313.0614 | Z24: 8202.9361 | AA24: 8572.0032 | AB24: 8847.8928 | AC24: 13529.727 | AD24: 14283.04 | AE24: 20219.657 | AF24: 22253.351 | AG24: 30711.913 | AH24: 32247.259 | AI24: 33366.379 | AJ24: 37730.305 | AK24: 40896.807 | AL24: 49667.452 | AM24: 51320.209 | AN24: 45665.461 | AO24: 44455.963 | AP24: 44556.688 | AQ24: 30628.288 | AR24: 32792.349 | AS24: 35788.531 | AT24: 48044.466 | AU24: 41694.421 | AV24: 48990.608 | AW24: 41494.635 | AX24: 45994.139 | AY24: 31689.93 | AZ24: 29193.869 | BA24: 26003.619 | BB24: 27581.434 | BC24: 17527.444 | BD24: 16541.645 | BE24: 13171.152 | BF24: 12286.51 | BG24: 14202.511 | BH24: 15106.191 | BI24: 21625.505 | BJ24: 24441.918 | BK24: 23872.773 | BL24: 25746.876
A25: - Other developing countries | D25: 314.0605 | E25: 540.3316 | F25: 284.6027 | G25: 291.8738 | H25: 698.1449 | I25: 787.88427 | J25: 491.64173 | K25: 315.89487 | L25: 44.180786 | M25: 31.525305 | N25: 104.78358 | O25: 72.846636 | P25: 70.909897 | Q25: 71.994318 | R25: 92.298421 | S25: 445.20072 | T25: 532.81528 | U25: 584.19202 | V25: 706.01932 | W25: 1395.9358 | X25: 1036.4337 | Y25: 1357.8506 | Z25: 2511.6924 | AA25: 5138.0125 | AB25: 7752.7024 | AC25: 12351.172 | AD25: 19629.34 | AE25: 23087.525 | AF25: 29644.348 | AG25: 34650.711 | AH25: 35985.5 | AI25: 42886.334 | AJ25: 37380.53 | AK25: 40269.432 | AL25: 53018.492 | AM25: 73425.671 | AN25: 66085.636 | AO25: 59923.189 | AP25: 59452.876 | AQ25: 60863.289 | AR25: 58189.96 | AS25: 62609.572 | AT25: 52351.989 | AU25: 58715.464 | AV25: 62408.09 | AW25: 76321.4 | AX25: 60333.317 | AY25: 64382.888 | AZ25: 85734.866 | BA25: 77730.597 | BB25: 95141.053 | BC25: 97068.109 | BD25: 109079.48 | BE25: 89050.261 | BF25: 117238.93 | BG25: 83055.503 | BH25: 90948.629 | BI25: 79727.743 | BJ25: 86862.212 | BK25: 85350.238 | BL25: 96361.648
A26: - Ex AEs | D26: 1570.6709 | E26: 2989.1422 | F26: 1862.291 | G26: 1807.6398 | H26: 3109.8886 | I26: 4054.3057 | J26: 2887.0433 | K26: 1851.0025 | L26: 2282.797 | M26: 2094.6905 | N26: 5300.8 | O26: 1199.9573 | P26: 2325.5401 | Q26: 2112.0456 | R26: 3101.9258 | S26: 3302.7902 | T26: 4563.8312 | U26: 10394.387 | V26: 10451.803 | W26: 14525.593 | X26: 11762.299 | Y26: 16414.421 | Z26: 50723.996 | AA26: 110510.34 | AB26: 117361.11 | AC26: 165924.17 | AD26: 246760.85 | AE26: 361336.32 | AF26: 299117.66 | AG26: 356341.13 | AH26: 449573.43 | AI26: 323601.88 | AJ26: 264499.51 | AK26: 315711.56 | AL26: 321413.55 | AM26: 240339.38 | AN26: 261244.19 | AO26: 217894.61 | AP26: 249949.77 | AQ26: 325096.08 | AR26: 261790.37 | AS26: 232672.91 | AT26: 364304.46 | AU26: 379074.39 | AV26: 384857.35 | AW26: 388102.3 | AX26: 257365.36 | AY26: 206220.1 | AZ26: 214644.81 | BA26: 199407.3 | BB26: 209332.8 | BC26: 174147.65 | BD26: 193208.88 | BE26: 170716.45 | BF26: 241500.01 | BG26: 207007.08 | BH26: 227443.94 | BI26: 189666.08 | BJ26: 233380.6 | BK26: 246255.83 | BL26: 386593.81
A28: Default Rates (%)
A29: - % of all Sovereigns | D29: 12.698413 | E29: 12.5 | F29: 11.764706 | G29: 12.408759 | H29: 13.475177 | I29: 16.551724 | J29: 11.409396 | K29: 12.666667 | L29: 12.337662 | M29: 10.967742 | N29: 21.656051 | O29: 24.223602 | P29: 29.192547 | Q29: 30.864198 | R29: 30.06135 | S29: 32.352941 | T29: 35.260116 | U29: 32.947977 | V29: 36.363636 | W29: 35.714286 | X29: 38.797814 | Y29: 41.621622 | Z29: 44.324324 | AA29: 45.698925 | AB29: 47.058824 | AC29: 46.524064 | AD29: 49.468085 | AE29: 48.404255 | AF29: 49.73545 | AG29: 52.380952 | AH29: 53.191489 | AI29: 48.792271 | AJ29: 52.403846 | AK29: 53.809524 | AL29: 54.028436 | AM29: 53.080569 | AN29: 53.554502 | AO29: 52.606635 | AP29: 53.554502 | AQ29: 52.132701 | AR29: 52.132701 | AS29: 52.606635 | AT29: 51.886792 | AU29: 51.886792 | AV29: 50 | AW29: 50.471698 | AX29: 47.887324 | AY29: 48.826291 | AZ29: 49.065421 | BA29: 47.196262 | BB29: 45.581395 | BC29: 47.906977 | BD29: 48.837209 | BE29: 49.302326 | BF29: 43.72093 | BG29: 46.046512 | BH29: 44.651163 | BI29: 46.046512 | BJ29: 44.186047 | BK29: 41.395349 | BL29: 41.395349
A30: - % of Paris Club Loans | AZ30: 17.373933 | BA30: 14.28793 | BB30: 15.214765 | BC30: 11.591334 | BD30: 16.028747 | BE30: 11.915696 | BF30: 14.453388 | BG30: 11.687878 | BH30: 12.109037 | BI30: 8.9748051 | BJ30: 11.074063 | BK30: 12.825047 | BL30: 12.758548
A31: - % of China Bilateral Offical Loans | AR31: 0.092200668 | AS31: 11.622299 | AT31: 19.689557 | AU31: 8.0103182 | AV31: 0.9153355 | AW31: 2.4194836 | AX31: 3.8602248 | AY31: 18.0691 | AZ31: 0.50069682 | BA31: 0.013960215 | BB31: 29.43176 | BC31: 14.381882 | BD31: 0.97658678 | BE31: 0.19558375 | BF31: 2.0612004 | BG31: 0.048840734 | BH31: 23.24818 | BI31: 3.6612046 | BJ31: 15.962667 | BK31: 12.405074 | BL31: 14.910243
A32: - % of World Public Debt | X32: 0.52790722 | Y32: 0.6839265 | Z32: 1.9224274 | AA32: 5.4085497 | AB32: 3.5688511 | AC32: 4.0841321 | AD32: 5.0663193 | AE32: 6.1313758 | AF32: 4.764663 | AG32: 5.5798977 | AH32: 6.1148712 | AI32: 3.6839092 | AJ32: 2.7554574 | AK32: 2.9019931 | AL32: 2.5910811 | AM32: 1.7757455 | AN32: 1.85253 | AO32: 1.5456749 | AP32: 1.5888132 | AQ32: 1.5491038 | AR32: 1.2402825 | AS32: 1.0589688 | AT32: 1.5642284 | AU32: 1.4224049 | AV32: 1.2452675 | AW32: 1.1978682 | AX32: 0.77875078 | AY32: 0.57974705 | AZ32: 0.52403612 | BA32: 0.44115484 | BB32: 0.41146606 | BC32: 0.30429004 | BD32: 0.8496553 | BE32: 0.87346471 | BF32: 0.38862022 | BG32: 0.35328422 | BH32: 0.40005083 | BI32: 0.35655781 | BJ32: 0.55813972 | BK32: 0.40998202 | BL32: 0.53871042
A33: - % of Emerging/Other Developing GDP (ex-China) | X33: 0.49065963 | Y33: 0.64656745 | Z33: 2.1170282 | AA33: 4.7510896 | AB33: 5.0695942 | AC33: 7.0098932 | AD33: 10.088342 | AE33: 13.392747 | AF33: 10.208794 | AG33: 11.149597 | AH33: 9.4112085 | AI33: 7.437414 | AJ33: 7.2864878 | AK33: 7.8127088 | AL33: 7.1760114 | AM33: 4.7432283 | AN33: 4.6526125 | AO33: 3.6781669 | AP33: 4.449088 | AQ33: 6.0776982 | AR33: 4.4704639 | AS33: 4.0276096 | AT33: 6.4867283 | AU33: 5.9967344 | AV33: 5.1020544 | AW33: 4.2817064 | AX33: 2.409054 | AY33: 1.5844308 | AZ33: 1.4010471 | BA33: 1.4328605 | BB33: 1.2447408 | BC33: 0.89583964 | BD33: 0.9688822 | BE33: 0.82780328 | BF33: 1.1680374 | BG33: 1.1252749 | BH33: 1.2449116 | BI33: 0.95310383 | BJ33: 1.1365906 | BK33: 1.1709694 | BL33: 2.0114434
A34: - % of World GDP | D34: 0.14207125 | E34: 0.23710542 | F34: 0.14748846 | G34: 0.12873755 | H34: 0.18986295 | I34: 0.22288333 | J34: 0.13586086 | K34: 0.081794187 | L34: 0.093518925 | M34: 0.077956475 | N34: 0.17962725 | O34: 0.036799683 | P34: 0.061856766 | Q34: 0.046104614 | R34: 0.058718182 | S34: 0.056135585 | T34: 0.07127811 | U34: 0.1435353 | V34: 0.12257124 | W34: 0.14661676 | X34: 0.10497288 | Y34: 0.14294238 | Z34: 0.4503262 | AA34: 0.95519173 | AB34: 0.97914641 | AC34: 1.326795 | AD34: 1.6729236 | AE34: 2.1270585 | AF34: 1.5667897 | AG34: 1.7745661 | AH34: 1.902762 | AI34: 1.3233916 | AJ34: 1.0451249 | AK34: 1.2143788 | AL34: 1.1501963 | AM34: 0.77155861 | AN34: 0.81595101 | AO34: 0.68239416 | AP34: 0.78660132 | AQ34: 0.98820428 | AR34: 0.77029571 | AS34: 0.69002853 | AT34: 1.0452917 | AU34: 0.96903617 | AV34: 0.87410596 | AW34: 0.81379189 | AX34: 0.4982732 | AY34: 0.3537488 | AZ34: 0.33574154 | BA34: 0.32918877 | BB34: 0.31601704 | BC34: 0.23685814 | BD34: 0.67497412 | BE34: 0.68267706 | BF34: 0.30509643 | BG34: 0.28068015 | BH34: 0.33265711 | BI34: 0.29228911 | BJ34: 0.45902202 | BK34: 0.34295586 | BL34: 0.52431385
A36: Total Number of Sovereigns | D36: 126 | E36: 128 | F36: 136 | G36: 137 | H36: 141 | I36: 145 | J36: 149 | K36: 150 | L36: 154 | M36: 155 | N36: 157 | O36: 161 | P36: 161 | Q36: 162 | R36: 163 | S36: 170 | T36: 173 | U36: 173 | V36: 176 | W36: 182 | X36: 183 | Y36: 185 | Z36: 185 | AA36: 186 | AB36: 187 | AC36: 187 | AD36: 188 | AE36: 188 | AF36: 189 | AG36: 189 | AH36: 188 | AI36: 207 | AJ36: 208 | AK36: 210 | AL36: 211 | AM36: 211 | AN36: 211 | AO36: 211 | AP36: 211 | AQ36: 211 | AR36: 211 | AS36: 211 | AT36: 212 | AU36: 212 | AV36: 212 | AW36: 212 | AX36: 213 | AY36: 213 | AZ36: 214 | BA36: 214 | BB36: 215 | BC36: 215 | BD36: 215 | BE36: 215 | BF36: 215 | BG36: 215 | BH36: 215 | BI36: 215 | BJ36: 215 | BK36: 215 | BL36: 215
A38: Sovereigns in Default | D38: 16 | E38: 16 | F38: 16 | G38: 17 | H38: 19 | I38: 24 | J38: 17 | K38: 19 | L38: 19 | M38: 17 | N38: 34 | O38: 39 | P38: 47 | Q38: 50 | R38: 49 | S38: 55 | T38: 61 | U38: 57 | V38: 64 | W38: 65 | X38: 71 | Y38: 77 | Z38: 82 | AA38: 85 | AB38: 88 | AC38: 87 | AD38: 93 | AE38: 91 | AF38: 94 | AG38: 99 | AH38: 100 | AI38: 101 | AJ38: 109 | AK38: 113 | AL38: 114 | AM38: 112 | AN38: 113 | AO38: 111 | AP38: 113 | AQ38: 110 | AR38: 110 | AS38: 111 | AT38: 110 | AU38: 110 | AV38: 106 | AW38: 107 | AX38: 102 | AY38: 104 | AZ38: 105 | BA38: 101 | BB38: 98 | BC38: 103 | BD38: 105 | BE38: 106 | BF38: 94 | BG38: 99 | BH38: 96 | BI38: 99 | BJ38: 95 | BK38: 89 | BL38: 89
A39: - IMF | D39: 3 | E39: 2 | F39: 2 | G39: 2 | H39: 4 | I39: 3 | J39: 3 | K39: 4 | L39: 2 | M39: 1 | N39: 0 | O39: 0 | P39: 0 | Q39: 0 | R39: 0 | S39: 1 | T39: 1 | U39: 1 | V39: 3 | W39: 4 | X39: 8 | Y39: 4 | Z39: 10 | AA39: 8 | AB39: 12 | AC39: 14 | AD39: 14 | AE39: 12 | AF39: 14 | AG39: 16 | AH39: 13 | AI39: 11 | AJ39: 15 | AK39: 15 | AL39: 12 | AM39: 10 | AN39: 8 | AO39: 8 | AP39: 8 | AQ39: 7 | AR39: 7 | AS39: 7 | AT39: 7 | AU39: 6 | AV39: 4 | AW39: 4 | AX39: 5 | AY39: 4 | AZ39: 4 | BA39: 3 | BB39: 3 | BC39: 3 | BD39: 3 | BE39: 3 | BF39: 3 | BG39: 4 | BH39: 3 | BI39: 2 | BJ39: 2 | BK39: 2 | BL39: 2
A40: - IBRD | AC40: 1 | AD40: 3 | AE40: 7 | AF40: 7 | AG40: 8 | AH40: 7 | AI40: 7 | AJ40: 9 | AK40: 8 | AL40: 7 | AM40: 7 | AN40: 7 | AO40: 8 | AP40: 8 | AQ40: 8 | AR40: 7 | AS40: 8 | AT40: 6 | AU40: 5 | AV40: 4 | AW40: 5 | AX40: 5 | AY40: 4 | AZ40: 4 | BA40: 1 | BB40: 1 | BC40: 1 | BD40: 1 | BE40: 2 | BF40: 1 | BG40: 1 | BH40: 1 | BI40: 1 | BJ40: 1 | BK40: 1 | BL40: 1
A41: - IDA | Y41: 1 | Z41: 1 | AA41: 1 | AB41: 1 | AC41: 0 | AD41: 0 | AE41: 0 | AF41: 5 | AG41: 7 | AH41: 5 | AI41: 4 | AJ41: 6 | AK41: 6 | AL41: 7 | AM41: 6 | AN41: 6 | AO41: 6 | AP41: 7 | AQ41: 8 | AR41: 7 | AS41: 8 | AT41: 11 | AU41: 8 | AV41: 8 | AW41: 8 | AX41: 8 | AY41: 8 | AZ41: 4 | BA41: 4 | BB41: 5 | BC41: 4 | BD41: 6 | BE41: 5 | BF41: 5 | BG41: 5 | BH41: 5 | BI41: 5 | BJ41: 5 | BK41: 5 | BL41: 5
A42: - Paris Club | D42: 0 | E42: 1 | F42: 2 | G42: 1 | H42: 1 | I42: 4 | J42: 2 | K42: 2 | L42: 3 | M42: 3 | N42: 2 | O42: 2 | P42: 4 | Q42: 3 | R42: 4 | S42: 4 | T42: 3 | U42: 6 | V42: 9 | W42: 8 | X42: 12 | Y42: 13 | Z42: 19 | AA42: 26 | AB42: 24 | AC42: 34 | AD42: 30 | AE42: 32 | AF42: 30 | AG42: 44 | AH42: 39 | AI42: 40 | AJ42: 37 | AK42: 34 | AL42: 37 | AM42: 37 | AN42: 37 | AO42: 27 | AP42: 29 | AQ42: 30 | AR42: 46 | AS42: 37 | AT42: 39 | AU42: 36 | AV42: 36 | AW42: 36 | AX42: 31 | AY42: 25 | AZ42: 23 | BA42: 19 | BB42: 20 | BC42: 16 | BD42: 13 | BE42: 11 | BF42: 10 | BG42: 11 | BH42: 10 | BI42: 11 | BJ42: 12 | BK42: 11 | BL42: 20
A43: - China | AR43: 2 | AS43: 16 | AT43: 8 | AU43: 8 | AV43: 3 | AW43: 6 | AX43: 7 | AY43: 23 | AZ43: 4 | BA43: 3 | BB43: 9 | BC43: 6 | BD43: 4 | BE43: 1 | BF43: 5 | BG43: 2 | BH43: 6 | BI43: 9 | BJ43: 11 | BK43: 9 | BL43: 22
A44: - Other official creditors | D44: 4 | E44: 6 | F44: 6 | G44: 7 | H44: 7 | I44: 14 | J44: 7 | K44: 5 | L44: 9 | M44: 8 | N44: 20 | O44: 28 | P44: 33 | Q44: 35 | R44: 35 | S44: 42 | T44: 45 | U44: 48 | V44: 53 | W44: 53 | X44: 56 | Y44: 61 | Z44: 65 | AA44: 72 | AB44: 76 | AC44: 72 | AD44: 77 | AE44: 80 | AF44: 84 | AG44: 88 | AH44: 91 | AI44: 93 | AJ44: 96 | AK44: 100 | AL44: 101 | AM44: 104 | AN44: 102 | AO44: 103 | AP44: 102 | AQ44: 101 | AR44: 100 | AS44: 102 | AT44: 105 | AU44: 100 | AV44: 100 | AW44: 99 | AX44: 97 | AY44: 96 | AZ44: 100 | BA44: 95 | BB44: 91 | BC44: 95 | BD44: 94 | BE44: 97 | BF44: 89 | BG44: 89 | BH44: 89 | BI44: 90 | BJ44: 84 | BK44: 80 | BL44: 76
A45: - FC bank loans | D45: 1 | E45: 3 | F45: 1 | G45: 2 | H45: 2 | I45: 2 | J45: 1 | K45: 1 | L45: 3 | M45: 1 | N45: 3 | O45: 0 | P45: 1 | Q45: 1 | R45: 0 | S45: 2 | T45: 6 | U45: 4 | V45: 7 | W45: 9 | X45: 12 | Y45: 17 | Z45: 25 | AA45: 32 | AB45: 36 | AC45: 38 | AD45: 42 | AE45: 43 | AF45: 44 | AG45: 44 | AH45: 47 | AI45: 43 | AJ45: 48 | AK45: 47 | AL45: 41 | AM45: 35 | AN45: 31 | AO45: 26 | AP45: 24 | AQ45: 21 | AR45: 20 | AS45: 18 | AT45: 20 | AU45: 18 | AV45: 18 | AW45: 15 | AX45: 12 | AY45: 10 | AZ45: 8 | BA45: 7 | BB45: 7 | BC45: 7 | BD45: 6 | BE45: 4 | BF45: 6 | BG45: 6 | BH45: 6 | BI45: 6 | BJ45: 8 | BK45: 8 | BL45: 6
A46: - FC bonds | D46: 9 | E46: 10 | F46: 9 | G46: 9 | H46: 9 | I46: 10 | J46: 8 | K46: 8 | L46: 7 | M46: 7 | N46: 6 | O46: 6 | P46: 6 | Q46: 6 | R46: 6 | S46: 6 | T46: 5 | U46: 3 | V46: 3 | W46: 3 | X46: 3 | Y46: 4 | Z46: 3 | AA46: 3 | AB46: 4 | AC46: 4 | AD46: 3 | AE46: 4 | AF46: 3 | AG46: 5 | AH46: 3 | AI46: 4 | AJ46: 6 | AK46: 4 | AL46: 5 | AM46: 3 | AN46: 3 | AO46: 2 | AP46: 4 | AQ46: 5 | AR46: 5 | AS46: 4 | AT46: 4 | AU46: 8 | AV46: 10 | AW46: 9 | AX46: 5 | AY46: 5 | AZ46: 7 | BA46: 7 | BB46: 8 | BC46: 7 | BD46: 8 | BE46: 9 | BF46: 5 | BG46: 7 | BH46: 8 | BI46: 10 | BJ46: 8 | BK46: 9 | BL46: 11
A47: - Other private creditors | D47: 1 | E47: 2 | F47: 1 | G47: 3 | H47: 1 | I47: 3 | J47: 0 | K47: 0 | L47: 1 | M47: 1 | N47: 19 | O47: 22 | P47: 24 | Q47: 30 | R47: 28 | S47: 33 | T47: 35 | U47: 30 | V47: 36 | W47: 37 | X47: 45 | Y47: 53 | Z47: 60 | AA47: 61 | AB47: 63 | AC47: 66 | AD47: 69 | AE47: 77 | AF47: 74 | AG47: 77 | AH47: 79 | AI47: 79 | AJ47: 85 | AK47: 88 | AL47: 91 | AM47: 91 | AN47: 80 | AO47: 76 | AP47: 78 | AQ47: 82 | AR47: 78 | AS47: 72 | AT47: 74 | AU47: 71 | AV47: 65 | AW47: 62 | AX47: 55 | AY47: 57 | AZ47: 58 | BA47: 54 | BB47: 54 | BC47: 52 | BD47: 51 | BE47: 48 | BF47: 47 | BG47: 44 | BH47: 42 | BI47: 44 | BJ47: 45 | BK47: 42 | BL47: 36
...

Sheet DATA 
A1: Below are individual country figures presented in the '2020 update' spreadsheet, rearranged for ease of statistical software input. Note: **** values have been replaced with #N/A and global total nominal US-dollar amounts for Paris Club, other official creditor and private creditor categories in 2020 are authors’ estimates.
A6: country | B6: country_group | C6: time | D6: Total | E6: - IMF | F6: - IBRD | G6: - IDA | H6: - Paris Club | I6: - China | J6: - Other official creditors | K6: - Other private creditors | L6: - FC bank loans | M6: - FC bonds | N6: - LC debt | O6: - Domestic arrears
A7: World | B7: World | C7: 1960 | D7: 1939.2725 | E7: 173 | F7: 0 | G7: 0 | H7: 0 | I7: 0 | J7: 79.8 | K7: 225 | L7: 1 | M7: 1349.4725 | N7: 111
A8: World | B8: World | C8: 1961 | D8: 3366.897 | E8: 53 | F8: 0 | G8: 0 | H8: 300 | I8: 0 | J8: 610.2 | K8: 306.81 | L8: 363.5 | M8: 1407.387 | N8: 326
A9: World | B9: World | C9: 1962 | D9: 2249.199 | E9: 54 | F9: 0 | G9: 0 | H9: 270 | I9: 0 | J9: 150.3 | K9: 248.81 | L9: 15 | M9: 1387.089 | N9: 124
A10: World | B10: World | C10: 1963 | D10: 2108.721 | E10: 25.3 | F10: 0 | G10: 0 | H10: 0 | I10: 0 | J10: 163.8 | K10: 413.81 | L10: 50 | M10: 1325.811 | N10: 130
A11: World | B11: World | C11: 1964 | D11: 3417.533 | E11: 211 | F11: 0 | G11: 0 | H11: 270 | I11: 0 | J11: 678.8 | K11: 272.81 | L11: 106 | M11: 1356.923 | N11: 522
A12: World | B12: World | C12: 1965 | D12: 4368.5133 | E12: 188.6 | F12: 0 | G12: 0 | H12: 297 | I12: 0 | J12: 1690.9 | K12: 341.81 | L12: 130.9 | M12: 1572.3033 | N12: 147
A13: World | B13: World | C13: 1966 | D13: 2887.0433 | E13: 114.65 | F13: 0 | G13: 0 | H13: 480 | I13: 0 | J13: 997.6 | K13: 0 | L13: 24 | M13: 1270.7933 | N13: 0
A14: World | B14: World | C14: 1967 | D14: 1851.0025 | E14: 40.15 | F14: 30 | G14: 0 | H14: 110 | I14: 0 | J14: 126.3 | K14: 0 | L14: 27 | M14: 1227.5525 | N14: 290
A15: World | B15: World | C15: 1968 | D15: 2282.797 | E15: 16.8 | F15: 1 | G15: 0 | H15: 484 | I15: 0 | J15: 743.1 | K15: 75 | L15: 104 | M15: 858.89697 | N15: 0
A16: World | B16: World | C16: 1969 | D16: 2094.6905 | E16: 3.5 | F16: 0 | G16: 0 | H16: 859 | I16: 0 | J16: 333 | K16: 1 | L16: 19 | M16: 879.19049 | N16: 0
A17: World | B17: World | C17: 1970 | D17: 5300.8 | E17: 0 | F17: 0 | G17: 0 | H17: 2112 | I17: 0 | J17: 1488.3811 | K17: 133.75961 | L17: 636.7 | M17: 817.95937 | N17: 112
A18: World | B18: World | C18: 1971 | D18: 1199.9573 | E18: 0 | F18: 0 | G18: 0 | H18: 0 | I18: 0 | J18: 197.45555 | K18: 144.75685 | L18: 0 | M18: 857.74494 | N18: 0
... A84: World | B84: World | C84: 2020 | D84: 443242.81 | E84: 4488 | F84: 1015 | G84: 1848 | H84: 44654.917 | I84: 22365.365 | J84: 102031.62 | K84: 21821.663 | L84: 15206.562 | M84: 224737.68 | N84: 5074
A85: Afghanistan | B85: HIPC countries | C85: 1960 | D85: 0 | E85: 0 | G85: 0 | H85: 0 | J85: 0 | K85: 0
A86: Afghanistan | B86: HIPC countries | C86: 1961 | D86: 0 | E86: 0 | G86: 0 | H86: 0 | J86: 0 | K86: 0
A87: Afghanistan | B87: HIPC countries | C87: 1962 | D87: 0 | E87: 0 | G87: 0 | H87: 0 | J87: 0 | K87: 0
A88: Afghanistan | B88: HIPC countries | C88: 1963 | D88: 0 | E88: 0 | G88: 0 | H88: 0 | J88: 0 | K88: 0
A89: Afghanistan | B89: HIPC countries | C89: 1964 | D89: 267 | E89: 0 | G89: 0 | H89: 0 | J89: 267 | K89: 0
A90: Afghanistan | B90: HIPC countries | C90: 1965 | D90: 267 | E90: 0 | G90: 0 | H90: 0 | J90: 267 | K90: 0
A91: Afghanistan | B91: HIPC countries | C91: 1966 | D91: 267 | E91: 0 | G91: 0 | H91: 0 | J91: 267 | K91: 0
A92: Afghanistan | B92: HIPC countries | C92: 1967 | D92: 2.7 | E92: 2.7 | G92: 0 | H92: 0 | J92: 0 | K92: 0
A93: Afghanistan | B93: HIPC countries | C93: 1968 | D93: 0 | E93: 0 | G93: 0 | H93: 0 | J93: 0 | K93: 0
A94: Afghanistan | B94: HIPC countries | C94: 1969 | D94: 0 | E94: 0 | G94: 0 | H94: 0 | J94: 0 | K94: 0
A95: Afghanistan | B95: HIPC countries | C95: 1970 | D95: 0 | E95: 0 | G95: 0 | H95: 0 | J95: 0 | K95: 0
A96: Afghanistan | B96: HIPC countries | C96: 1971 | D96: 0 | E96: 0 | G96: 0 | H96: 0 | J96: 0 | K96: 0
... A122: Afghanistan | B122: HIPC countries | C122: 1980 | D122: 15 | E122: 0 | G122: 0 | H122: 0 | J122: 15 | K122: 0
A123: Afghanistan | B123: HIPC countries | C123: 1981 | D123: 0 | E123: 0 | G123: 0 | H123: 0 | J123: #N/A | K123: 0
A124: Afghanistan | B124: HIPC countries | C124: 1982 | D124: 3 | E124: 0 | G124: 0 | H124: 0 | J124: 3 | K124: 0
A125: Afghanistan | B125: HIPC countries | C125: 1983 | D125: 0 | E125: 0 | G125: 0 | H125: 0 | J125: #N/A | K125: 0
A126: Afghanistan | B126: HIPC countries | C126: 1984 | D126: 0 | E126: 0 | G126: 0 | H126: 0 | J126: #N/A | K126: 0
A127: Afghanistan | B127: HIPC countries | C127: 1985 | D127: 10 | E127: 0 | G127: 0 | H127: 0 | J127: 10 | K127: 0
A128: Afghanistan | B128: HIPC countries | C128: 1986 | D128: 10 | E128: 0 | G128: 0 | H128: 0 | J128: 10 | K128: 0
A129: Afghanistan | B129: HIPC countries | C129: 1987 | D129: 0 | E129: 0 | G129: 0 | H129: 0 | J129: 0 | K129: 0
A130: Afghanistan | B130: HIPC countries | C130: 1988 | D130: 0 | E130: 0 | G130: 0 | H130: 0 | J130: 0 | K130: 0
A131: Afghanistan | B131: HIPC countries | C131: 1989 | D131: 0.372 | E131: 0 | G131: 0.372 | H131: 0 | J131: 0 | K131: 0
A132: Afghanistan | B132: HIPC countries | C132: 1990 | D132: 0 | E132: 0 | G132: 0 | H132: 0 | J132: 0 | K132: 0
A133: Afghanistan | B133: HIPC countries | C133: 1991 | D133: 0 | E133: 0 | G133: 0 | H133: 0 | J133: 0 | K133: 0
A134: Afghanistan | B134: HIPC countries | C134: 1992 | D134: 5 | E134: 0 | G134: 1 | J134: 4 | K134: 0
...

Sheet DEBTTOTAL
B1: 1960 | C1: 1961 | D1: 1962 | E1: 1963 | F1: 1964 | G1: 1965 | H1: 1966 | I1: 1967 | J1: 1968 | K1: 1969 | L1: 1970 | M1: 1971 | N1: 1972 | O1: 1973 | P1: 1974 | Q1: 1975 | R1: 1976 | S1: 1977 | T1: 1978 | U1: 1979 | V1: 1980 | W1: 1981 | X1: 1982 | Y1: 1983 | Z1: 1984 | AA1: 1985 | AB1: 1986 | AC1: 1987 | AD1: 1988 | AE1: 1989 | AF1: 1990 | AG1: 1991 | AH1: 1992 | AI1: 1993 | AJ1: 1994 | AK1: 1995 | AL1: 1996 | AM1: 1997 | AN1: 1998 | AO1: 1999 | AP1: 2000 | AQ1: 2001 | AR1: 2002 | AS1: 2003 | AT1: 2004 | AU1: 2005 | AV1: 2006 | AW1: 2007 | AX1: 2008 | AY1: 2009 | AZ1: 2010 | BA1: 2011 | BB1: 2012 | BC1: 2013 | BD1: 2014 | BE1: 2015 | BF1: 2016 | BG1: 2017 | BH1: 2018 | BI1: 2019 | BJ1: 2020
A2: Afghanistan | B2: 0 | C2: 0 | D2: 0 | E2: 0 | F2: 267 | G2: 267 | H2: 267 | I2: 2.7 | J2: 0 | K2: 0 | L2: 0 | M2: 0 | N2: 37 | O2: 0 | P2: 0 | Q2: 0 | R2: 437 | S2: 0 | T2: 0 | U2: 0 | V2: 15 | W2: 0 | X2: 3 | Y2: 0 | Z2: 0 | AA2: 10 | AB2: 10 | AC2: 0 | AD2: 0 | AE2: 0.372 | AF2: 0 | AG2: 0 | AH2: 5 | AI2: 7 | AJ2: 22 | AK2: 24.6 | AL2: 27.5 | AM2: 32.674327 | AN2: 37.687987 | AO2: 42.192288 | AP2: 284.26502 | AQ2: 288.7907 | AR2: 11394.048 | AS2: 11302 | AT2: 11306 | AU2: 11305 | AV2: 11284.421 | AW2: 148.3124 | AX2: 125.4213 | AY2: 88.53993 | AZ2: 1027 | BA2: 275.7879 | BB2: 173.89731 | BC2: 200.01085 | BD2: 313.09405 | BE2: 359.58915 | BF2: 437.13654 | BG2: 521.12701 | BH2: 596.772 | BI2: 670.553 | BJ2: 714.3
A3: Albania | B3: 0 | C3: 0 | D3: 0 | E3: 0 | F3: 0 | G3: 0 | H3: 0 | I3: 0 | J3: 0 | K3: 0 | L3: 0 | M3: 0 | N3: 0 | O3: 0 | P3: 0 | Q3: 0 | R3: 0 | S3: 0 | T3: 0 | U3: 0 | V3: 0 | W3: 0 | X3: 0 | Y3: 0 | Z3: 0 | AA3: 0 | AB3: 0 | AC3: 0 | AD3: 0 | AE3: 0 | AF3: 0 | AG3: 425 | AH3: 446.023 | AI3: 571.793 | AJ3: 511.848 | AK3: 745.262 | AL3: 34.958 | AM3: 34.402 | AN3: 109.435 | AO3: 34.534 | AP3: 383.268 | AQ3: 271.273 | AR3: 91.072 | AS3: 15.982 | AT3: 19.619 | AU3: 15.774 | AV3: 17.651 | AW3: 16.834 | AX3: 8.7 | AY3: 0.305 | AZ3: 0 | BA3: 0 | BB3: 0 | BC3: 1.232 | BD3: 0 | BE3: 0 | BF3: 0 | BG3: 0.6 | BH3: 0 | BI3: 0.0548619 | BJ3: 0
A4: Algeria | B4: 0 | C4: 0 | D4: 0 | E4: 0 | F4: 0 | G4: 0 | H4: 0 | I4: 0 | J4: 0 | K4: 0 | L4: 0 | M4: 0 | N4: 0 | O4: 0 | P4: 0 | Q4: 0 | R4: 6.423 | S4: 13.012 | T4: 0.959 | U4: 3.486 | V4: 1.7 | W4: 1.7 | X4: 1.7 | Y4: 1.7 | Z4: 0 | AA4: 0 | AB4: 0 | AC4: 0.016 | AD4: 0.016 | AE4: 0 | AF4: 0.764 | AG4: 1260.359 | AH4: 1464.594 | AI4: 910.675 | AJ4: 9540.029 | AK4: 12108.181 | AL4: 3537.518 | AM4: 2212.957 | AN4: 542.532 | AO4: 0 | AP4: 0 | AQ4: 0 | AR4: 0.034 | AS4: 0.01 | AT4: 0.011 | AU4: 4700 | AV4: 0 | AW4: 0 | AX4: 0 | AY4: 0 | AZ4: 0 | BA4: 0 | BB4: 76.7 | BC4: 0 | BD4: 0 | BE4: 0 | BF4: 0 | BG4: 45.6 | BH4: 0.1712819 | BI4: 0 | BJ4: 0
A5: Angola | B5: 0 | C5: 0 | D5: 0 | E5: 0 | F5: 0 | G5: 0 | H5: 0 | I5: 0 | J5: 0 | K5: 0 | L5: 0 | M5: 0 | N5: 0 | O5: 0 | P5: 0 | Q5: 0 | R5: 0 | S5: 0 | T5: 0 | U5: 0 | V5: 0 | W5: 0 | X5: 0 | Y5: 0 | Z5: 0 | AA5: 0 | AB5: 0 | AC5: 0 | AD5: 0 | AE5: 1082.1946 | AF5: 1767.1669 | AG5: 1538.2281 | AH5: 2572.7462 | AI5: 4063.516 | AJ5: 5163.703 | AK5: 5865.977 | AL5: 7330.006 | AM5: 3236.477 | AN5: 5123.868 | AO5: 4613.296 | AP5: 3738.7837 | AQ5: 4370.445 | AR5: 4385.53 | AS5: 5191.557 | AT5: 3760.011 | AU5: 3259.434 | AV5: 2823.3576 | AW5: 519.2935 | AX5: 353.36465 | AY5: 405.05913 | AZ5: 366.34275 | BA5: 333.70492 | BB5: 321.60291 | BC5: 333.93393 | BD5: 326.85534 | BE5: 295.12037 | BF5: 3387.874 | BG5: 110.44183 | BH5: 84.413495 | BI5: 83.395495 | BJ5: 8593.9
A6: Antigua and Barbuda | B6: 0 | C6: 0 | D6: 0 | E6: 0 | F6: 0 | G6: 0 | H6: 0 | I6: 0 | J6: 0 | K6: 0 | L6: 0 | M6: 0 | N6: 0 | O6: 0 | P6: 0 | Q6: 0 | R6: 0 | S6: 0 | T6: 0 | U6: 0 | V6: 0 | W6: 0 | X6: 0 | Y6: 0 | Z6: 0 | AA6: 24 | AB6: 32 | AC6: 0 | AD6: 0 | AE6: 0 | AF6: 0 | AG6: 0 | AH6: 0 | AI6: 0 | AJ6: 0 | AK6: 0 | AL6: 161 | AM6: 175 | AN6: 391 | AO6: 702.114 | AP6: 739.90141 | AQ6: 598 | AR6: 649 | AS6: 794 | AT6: 838 | AU6: 764 | AV6: 762 | AW6: 612 | AX6: 631 | AY6: 707 | AZ6: 684 | BA6: 515 | BB6: 0.4 | BC6: 2.9 | BD6: 18.6 | BE6: 20 | BF6: 8 | BG6: 14 | BH6: 28 | BI6: 21 | BJ6: 42.9
A7: Argentina | B7: 100 | C7: 462 | D7: 362 | E7: 15 | F7: 0 | G7: 472 | H7: 0 | I7: 0 | J7: 0 | K7: 0 | L7: 0 | M7: 0 | N7: 0 | O7: 0 | P7: 0 | Q7: 0 | R7: 970 | S7: 0 | T7: 0 | U7: 0 | V7: 0 | W7: 0 | X7: 3870 | Y7: 3507.1 | Z7: 4469.523 | AA7: 11649.7 | AB7: 4655.523 | AC7: 31736.4 | AD7: 23529.3 | AE7: 35530.3 | AF7: 31834.9 | AG7: 34415.3 | AH7: 32232.3 | AI7: 28476 | AJ7: 10.551 | AK7: 69.225 | AL7: 0.173 | AM7: 0 | AN7: 0 | AO7: 0 | AP7: 10.316 | AQ7: 41000 | AR7: 103289 | AS7: 116644 | AT7: 115873 | AU7: 109529.7 | AV7: 34249 | AW7: 35984 | AX7: 36220 | AY7: 36732 | AZ7: 18068 | BA7: 17696 | BB7: 17750 | BC7: 17839 | BD7: 55874 | BE7: 44536 | BF7: 47301 | BG7: 3415 | BH7: 1241 | BI7: 13400 | BJ7: 72724
A8: Armenia | B8: 0 | C8: 0 | D8: 0 | E8: 0 | F8: 0 | G8: 0 | H8: 0 | I8: 0 | J8: 0 | K8: 0 | L8: 0 | M8: 0 | N8: 0 | O8: 0 | P8: 0 | Q8: 0 | R8: 0 | S8: 0 | T8: 0 | U8: 0 | V8: 0 | W8: 0 | X8: 0 | Y8: 0 | Z8: 0 | AA8: 0 | AB8: 0 | AC8: 0 | AD8: 0 | AE8: 0 | AF8: 0 | AG8: 0 | AH8: 0 | AI8: 30.8 | AJ8: 32.229 | AK8: 76.577 | AL8: 64.034 | AM8: 126.885 | AN8: 31.314 | AO8: 0 | AP8: 24.915 | AQ8: 17.548 | AR8: 14.142 | AS8: 46.06 | AT8: 0 | AU8: 0 | AV8: 0 | AW8: 0 | AX8: 0 | AY8: 0 | AZ8: 0 | BA8: 0 | BB8: 0 | BC8: 0 | BD8: 0 | BE8: 0 | BF8: 0 | BG8: 0 | BH8: 0 | BI8: 0 | BJ8: 0
A9: Azerbaijan | B9: 0 | C9: 0 | D9: 0 | E9: 0 | F9: 0 | G9: 0 | H9: 0 | I9: 0 | J9: 0 | K9: 0 | L9: 0 | M9: 0 | N9: 0 | O9: 0 | P9: 0 | Q9: 0 | R9: 0 | S9: 0 | T9: 0 | U9: 0 | V9: 0 | W9: 0 | X9: 0 | Y9: 0 | Z9: 0 | AA9: 0 | AB9: 0 | AC9: 0 | AD9: 0 | AE9: 0 | AF9: 0 | AG9: 0 | AH9: 0 | AI9: 0 | AJ9: 23.899 | AK9: 41.532 | AL9: 37.981 | AM9: 37.981 | AN9: 0 | AO9: 0 | AP9: 0 | AQ9: 0 | AR9: 0 | AS9: 0 | AT9: 74.817 | AU9: 0 | AV9: 0 | AW9: 0 | AX9: 0 | AY9: 0 | AZ9: 0 | BA9: 0 | BB9: 0 | BC9: 0 | BD9: 0 | BE9: 0 | BF9: 0 | BG9: 0 | BH9: 0 | BI9: 0 | BJ9: 0
A10: Bahamas | B10: 0 | C10: 0 | D10: 0 | E10: 0 | F10: 0 | G10: 0 | H10: 0 | I10: 0 | J10: 0 | K10: 0 | L10: 0 | M10: 0 | N10: 0 | O10: 0 | P10: 0 | Q10: 0 | R10: 0 | S10: 0 | T10: 0 | U10: 0 | V10: 0 | W10: 0 | X10: 0 | Y10: 0 | Z10: 0 | AA10: 0 | AB10: 0 | AC10: 0 | AD10: 0 | AE10: 0 | AF10: 0 | AG10: 0 | AH10: 0 | AI10: 0 | AJ10: 0 | AK10: 0 | AL10: 0 | AM10: 0 | AN10: 0 | AO10: 0 | AP10: 0 | AQ10: 0 | AR10: 0 | AS10: 0 | AT10: 0 | AU10: 0 | AV10: 0 | AW10: 0 | AX10: 0 | AY10: 0 | AZ10: 0 | BA10: 0 | BB10: 0 | BC10: 0 | BD10: 0 | BE10: 0 | BF10: 0 | BG10: 0 | BH10: 0 | BI10: 0 | BJ10: 0
A11: Bangladesh | B11: 0 | D11: 0 | F11: 0 | H11: 0 | J11: 0 | L11: 0 | N11: 0 | O11: 0.53 | P11: 1.033 | Q11: 2.027 | R11: 3.225 | S11: 4.046 | T11: 5.459 | U11: 1.275 | V11: 0.243 | W11: 0.258 | X11: 0.27 | Y11: 0.289 | Z11: 0.267 | AA11: 1.199 | AB11: 2.567 | AC11: 8.189 | AD11: 8.897 | AE11: 10.41 | AF11: 12.52 | AG11: 309.22 | AH11: 14.076 | AI11: 17.5 | AJ11: 27.657 | AK11: 28.227 | AL11: 3.394 | AM11: 3.214 | AN11: 3.532 | AO11: 4.401 | AP11: 4.401 | AQ11: 78.253 | AR11: 102.08 | AS11: 117.805 | AT11: 161.543 | AU11: 17.245 | AV11: 86.393 | AW11: 211.431 | AX11: 536.705 | AY11: 8.195 | AZ11: 256.30631 | BA11: 119.45911 | BB11: 58.667197 | BC11: 26.883064 | BD11: 8.8727516 | BE11: 0 | BF11: 0 | BG11: 0 | BH11: 0 | BI11: 0 | BJ11: 0
A12: Barbados | B12: 0 | C12: 0 | D12: 0 | E12: 0 | F12: 0 | G12: 0 | H12: 0 | I12: 0 | J12: 0 | K12: 0 | L12: 0 | M12: 0 | N12: 0 | O12: 0 | P12: 0 | Q12: 0 | R12: 0 | S12: 0 | T12: 0 | U12: 0 | V12: 0 | W12: 0 | X12: 0 | Y12: 0 | Z12: 0 | AA12: 0 | AB12: 0 | AC12: 0 | AD12: 0 | AE12: 0 | AF12: 0 | AG12: 0 | AH12: 0 | AI12: 0 | AJ12: 0 | AK12: 0 | AL12: 0 | AM12: 0 | AN12: 0 | AO12: 0 | AP12: 0 | AQ12: 0 | AR12: 0 | AS12: 0 | AT12: 0 | AU12: 0 | AV12: 0 | AW12: 0 | AX12: 0 | AY12: 0 | AZ12: 0 | BA12: 0 | BB12: 0 | BC12: 0 | BD12: 0 | BE12: 0 | BF12: 0 | BG12: 0 | BH12: 6960.4 | BI12: 1101.4 | BJ12: 25
A13: Belarus | B13: 0 | C13: 0 | D13: 0 | E13: 0 | F13: 0 | G13: 0 | H13: 0 | I13: 0 | J13: 0 | K13: 0 | L13: 0 | M13: 0 | N13: 0 | O13: 0 | P13: 0 | Q13: 0 | R13: 0 | S13: 0 | T13: 0 | U13: 0 | V13: 0 | W13: 0 | X13: 0 | Y13: 0 | Z13: 0 | AA13: 0 | AB13: 0 | AC13: 0 | AD13: 0 | AE13: 0 | AF13: 0 | AG13: 0 | AH13: 0 | AI13: 6.933 | AJ13: 149.758 | AK13: 158.503 | AL13: 588.884 | AM13: 4.136 | AN13: 15.751 | AO13: 32.846 | AP13: 42.43392 | AQ13: 35.5041 | AR13: 4.557403 | AS13: 20.93 | AT13: 0.511 | AU13: 37.637 | AV13: 26.318 | AW13: 11.896 | AX13: 5.477 | AY13: 37.103 | AZ13: 10.642 | BA13: 16.1 | BB13: 12.227 | BC13: 12.462 | BD13: 15.216 | BE13: 14.519 | BF13: 11.487 | BG13: 11.612 | BH13: 12.161 | BI13: 14.629 | BJ13: 14.629
A14: Belize | B14: 0 | C14: 0 | D14: 0 | E14: 0 | F14: 0 | G14: 0 | H14: 0 | I14: 0 | J14: 0 | K14: 0 | L14: 0 | M14: 0 | N14: 0 | W14: 0.197632 | X14: 0.472821 | Y14: 3.230595 | Z14: 6.144993 | AA14: 0.488055 | AB14: 2.702375 | AC14: 2.460519 | AD14: 3.563852 | AE14: 2.642822 | AF14: 12.01195 | AG14: 1.764069 | AH14: 3.048357 | AI14: 4.723085 | AJ14: 8.268537 | AK14: 1.545853 | AL14: 1.179583 | AM14: 0.014 | AN14: 0 | AO14: 8.64e-05 | AP14: 0 | AQ14: 0.012 | AR14: 1.899912 | AS14: 0.983129 | AT14: 1.307858 | AU14: 8.724944 | AV14: 555.14936 | AW14: 558.26718 | AX14: 8.183571 | AY14: 10.761639 | AZ14: 7.8089342 | BA14: 8.2695553 | BB14: 550.20034 | BC14: 561.23872 | BD14: 6.0339148 | BE14: 7.2783801 | BF14: 4.1031292 | BG14: 532.92937 | BH14: 13.564791 | BI14: 22.731 | BJ14: 629
A15: Benin | B15: 0.8 | C15: 0.8 | D15: 0.8 | E15: 0.8 | F15: 0.8 | G15: 4.3 | H15: 4.3 | I15: 14 | J15: 14 | K15: 14 | L15: 4.340489 | M15: 5.999383 | N15: 9.316107 | O15: 12.619379 | P15: 14.759542 | Q15: 16.719825 | R15: 15.442523 | S15: 16.832511 | T15: 19.098179 | U15: 20.004136 | V15: 18.905969 | W15: 15.504892 | X15: 4.996686 | Y15: 44.907587 | Z15: 87.56664 | AA15: 166.74584 | AB15: 265.92719 | AC15: 394.35031 | AD15: 440.11551 | AE15: 360.262 | AF15: 226.145 | AG15: 161.963 | AH15: 105.18034 | AI15: 97.004 | AJ15: 96.76503 | AK15: 224.9738 | AL15: 212.869 | AM15: 80.56646 | AN15: 81.2975 | AO15: 81.3369 | AP15: 62.9436 | AQ15: 24.40615 | AR15: 20.82265 | AS15: 65 | AT15: 24 | AU15: 22.90741 | AV15: 13.80703 | AW15: 14.12124 | AX15: 22.88658 | AY15: 68.31789 | AZ15: 62.906068 | BA15: 64.897601 | BB15: 97.700349 | BC15: 107.31058 | BD15: 56.144357 | BE15: 102.92848 | BF15: 94.135442 | BG15: 103.22736 | BH15: 106.01467 | BI15: 21.098191 | BJ15: 21.098191
A16: Bhutan | B16: 0 | C16: 0 | D16: 0 | E16: 0 | F16: 0 | G16: 0 | H16: 0 | I16: 0 | J16: 0 | K16: 0 | L16: 0 | M16: 0 | N16: 0 | O16: 0 | P16: 0 | Q16: 0 | R16: 0 | S16: 0 | T16: 0 | U16: 0 | V16: 0 | W16: 0 | X16: 0 | Y16: 0 | Z16: 0 | AA16: 0 | AB16: 0 | AC16: 0 | AD16: 0 | AE16: 0 | AF16: 1.72 | AG16: 3.541 | AH16: 3.488 | AI16: 2.842 | AJ16: 2.034 | AK16: 0.814 | AL16: 0.277 | AM16: 0 | AN16: 0 | AO16: 0 | AP16: 0 | AQ16: 0 | AR16: 0 | AS16: 0 | AT16: 0 | AU16: 8.618 | AV16: 0 | AW16: 0 | AX16: 0 | AY16: 0 | AZ16: 0 | BA16: 0 | BB16: 0 | BC16: 0 | BD16: 0 | BE16: 0 | BF16: 0 | BG16: 0 | BH16: 0 | BI16: 0 | BJ16: 0
A17: Bolivia | B17: 116.547 | C17: 121.19 | D17: 97.833 | E17: 102.776 | F17: 106.119 | G17: 109.762 | H17: 112.405 | I17: 72.048 | J17: 74.691 | K17: 77.334 | L17: 2.999 | M17: 5.298 | N17: 4.134 | O17: 6.378 | P17: 5.418 | Q17: 5.225 | R17: 5.225 | S17: 5.225 | T17: 6.663 | U17: 26.6888 | V17: 196.20253 | W17: 558.16253 | X17: 310.08103 | Y17: 735.1463 | Z17: 586.7305 | AA17: 891.3576 | AB17: 2268.4062 | AC17: 2157.8275 | AD17: 958.55435 | AE17: 1255.8836 | AF17: 560.5145 | AG17: 800.735 | AH17: 424.43073 | AI17: 555.6749 | AJ17: 168.5568 | AK17: 1402.9203 | AL17: 709.12834 | AM17: 442.04474 | AN17: 570.385 | AO17: 76.19946 | AP17: 67.10209 | AQ17: 685 | AR17: 65.32556 | AS17: 55.66054 | AT17: 85.82444 | AU17: 68.0878 | AV17: 44.362762 | AW17: 440.8882 | AX17: 16.84087 | AY17: 12.27535 | AZ17: 0 | BA17: 0 | BB17: 0 | BC17: 0 | BD17: 0.442 | BE17: 0 | BF17: 0 | BG17: 0.86552 | BH17: 0 | BI17: 0 | BJ17: 0
A18: Bosnia & Herzegovina | B18: 0 | C18: 0 | D18: 0 | E18: 0 | F18: 0 | G18: 0 | H18: 0 | I18: 0 | J18: 0 | K18: 0 | L18: 0 | M18: 0 | N18: 0 | O18: 0 | P18: 0 | Q18: 0 | R18: 0 | S18: 0 | T18: 0 | U18: 0 | V18: 0 | W18: 0 | X18: 0 | Y18: 0 | Z18: 0 | AA18: 0 | AB18: 0 | AC18: 0 | AD18: 0 | AE18: 0 | AF18: 0 | AG18: 0 | AH18: 972.1776 | AI18: 1110.1312 | AJ18: 1181.3566 | AK18: 1268.0606 | AL18: 1852 | AM18: 1879 | AN18: 1145 | AO18: 1349.1182 | AP18: 709.144 | AQ18: 4.25 | AR18: 5.281 | AS18: 24.02 | AT18: 3.59 | AU18: 3.79 | AV18: 4.61 | AW18: 5.99 | AX18: 6.83 | AY18: 30.211 | AZ18: 1.69 | BA18: 2.39 | BB18: 0 | BC18: 0 | BD18: 0 | BE18: 0 | BF18: 0.599 | BG18: 14.474706 | BH18: 0 | BI18: 0 | BJ18: 0
A19: Botswana | B19: 0 | C19: 0 | D19: 0 | E19: 0 | F19: 0 | G19: 0 | H19: 0 | I19: 0 | J19: 0 | K19: 0 | L19: 0 | M19: 0 | N19: 0 | O19: 0 | P19: 0 | Q19: 0 | R19: 0 | S19: 0 | T19: 0 | U19: 0.273 | V19: 0 | W19: 0 | X19: 0 | Y19: 0 | Z19: 0 | AA19: 0 | AB19: 0.112 | AC19: 1.807 | AD19: 0.983 | AE19: 2.646 | AF19: 7.266 | AG19: 9.121 | AH19: 12.696 | AI19: 13.59 | AJ19: 22.056 | AK19: 16.858 | AL19: 1.633 | AM19: 2.055 | AN19: 4.186 | AO19: 4.198 | AP19: 4.858 | AQ19: 3.827 | AR19: 1.44 | AS19: 2.84 | AT19: 1.006 | AU19: 5.49 | AV19: 32.033 | AW19: 2.6 | AX19: 457.64 | AY19: 0.525 | AZ19: 0.29 | BA19: 0.29 | BB19: 0.27 | BC19: 0.27 | BD19: 0.24 | BE19: 0.19 | BF19: 0 | BG19: 0.0042724 | BH19: 7.3319882 | BI19: 0.0013828 | BJ19: 0
A20: Brazil | B20: 48 | C20: 811.6 | D20: 43.5 | E20: 112 | F20: 416 | G20: 43 | H20: 0 | I20: 0 | J20: 0 | K20: 0 | L20: 0 | M20: 20.8 | N20: 35 | O20: 40.8 | P20: 39.8 | Q20: 47.371 | R20: 62.83 | S20: 137.893 | T20: 286.377 | U20: 352.69 | V20: 411.435 | W20: 439.478 | X20: 441.296 | Y20: 28266.533 | Z20: 26641.555 | AA20: 17329.883 | AB20: 54301.686 | AC20: 98751.7 | AD20: 68315.1 | AE20: 85564.52 | AF20: 147531.9 | AG20: 28411.036 | AH20: 31888.5 | AI20: 63096.476 | AJ20: 92622.26 | AK20: 5450.458 | AL20: 4901.753 | AM20: 10851.409 | AN20: 3561.105 | AO20: 10647.549 | AP20: 14955.63 | AQ20: 0 | AR20: 0 | AS20: 0.2 | AT20: 0.019 | AU20: 4274.213 | AV20: 104.844 | AW20: 24.1 | AX20: 112.634 | AY20: 47.895 | AZ20: 83.765 | BA20: 1.867 | BB20: 1.458 | BC20: 102.702 | BD20: 1229.618 | BE20: 40.775 | BF20: 6.017 | BG20: 3.297 | BH20: 0 | BI20: 0 | BJ20: 0
A21: Bulgaria | B21: 131.6891 | C21: 133.7759 | D21: 135.8627 | E21: 137.9495 | F21: 140.0363 | G21: 142.1231 | H21: 144.2099 | I21: 128.2171 | J21: 130.0735 | K21: 131.9299 | L21: 133.31703 | M21: 141.81809 | N21: 134.61436 | O21: 135.4631 | P21: 137.76573 | Q21: 124.14164 | R21: 108.64894 | S21: 118.75365 | T21: 127.50815 | U21: 140.0717 | V21: 123.81445 | W21: 101.1997 | X21: 87.21918 | Y21: 77.81345 | Z21: 65.43929 | AA21: 80.01648 | AB21: 80.84592 | AC21: 103.79577 | AD21: 0 | AE21: 3.1 | AF21: 6484.8 | AG21: 7651 | AH21: 7984 | AI21: 8222.06 | AJ21: 8110 | AK21: 342.4 | AL21: 231.87 | AM21: 514.76 | AN21: 267.48 | AO21: 350.39 | AP21: 19.36 | AQ21: 226.56 | AR21: 22.75 | AS21: 4.51 | AT21: 38.6 | AU21: 72.17 | AV21: 14.25 | AW21: 19.61 | AX21: 86.32 | AY21: 122.89 | AZ21: 0 | BA21: 0 | BB21: 0 | BC21: 0.96 | BD21: 0.02 | BE21: 0 | BF21: 0 | BG21: 0 | BH21: 0 | BI21: 0 | BJ21: 0
A22: Burkina Faso | B22: 0 | C22: 0 | D22: 0 | E22: 0 | F22: 0 | G22: 0 | H22: 0 | I22: 0 | J22: 0 | K22: 0 | L22: 0 | M22: 0 | N22: 0 | O22: 0 | P22: 0 | Q22: 0 | R22: 0 | S22: 0 | T22: 0.01 | U22: 0.05 | V22: 0.25 | W22: 0.24 | X22: 1.13 | Y22: 0.99 | Z22: 7.27 | AA22: 12.33 | AB22: 30.97 | AC22: 51.93 | AD22: 61.02 | AE22: 255.91 | AF22: 90.52 | AG22: 129.297 | AH22: 52.438 | AI22: 91.594 | AJ22: 166.336 | AK22: 63.938 | AL22: 111.1 | AM22: 40.837 | AN22: 47.257 | AO22: 44.013 | AP22: 232.7 | AQ22: 68.401 | AR22: 137.7 | AS22: 81.075 | AT22: 181.387 | AU22: 94.112 | AV22: 1329.363 | AW22: 39.273 | AX22: 40.848 | AY22: 36.858 | AZ22: 41.037 | BA22: 34.237 | BB22: 34.462 | BC22: 35.1766 | BD22: 35.09632 | BE22: 34.62587 | BF22: 79.81449 | BG22: 87.33523 | BH22: 83.523951 | BI22: 82.613947 | BJ22: 84
A23: Burundi | B23: 0 | C23: 0 | D23: 0 | E23: 0 | F23: 0 | G23: 0 | H23: 0 | I23: 0 | J23: 0 | K23: 0 | L23: 0 | M23: 0.051408 | N23: 0.156153 | O23: 0.307066 | P23: 0 | Q23: 0 | R23: 0 | S23: 0 | T23: 0 | U23: 0 | V23: 0 | W23: 0 | X23: 2.6005 | Y23: 5.0482 | Z23: 5.393457 | AA23: 7.32057 | AB23: 9.832113 | AC23: 10.974013 | AD23: 1.72972 | AE23: 1.32071 | AF23: 0.729982 | AG23: 0.069691 | AH23: 6.170704 | AI23: 13.271309 | AJ23: 12.705123 | AK23: 5.881301 | AL23: 19.903632 | AM23: 35.526891 | AN23: 56.149841 | AO23: 78.436411 | AP23: 101.81277 | AQ23: 106.5866 | AR23: 131.9666 | AS23: 161.459 | AT23: 140.65245 | AU23: 110.56508 | AV23: 120.80964 | AW23: 77.82605 | AX23: 65.50228 | AY23: 134 | AZ23: 15.271744 | BA23: 48.196555 | BB23: 5.073 | BC23: 6.675 | BD23: 5.702 | BE23: 6.14 | BF23: 5.726 | BG23: 5.7148483 | BH23: 5.7247816 | BI23: 5.7047656 | BJ23: 10.5
A24: Cabo Verde | B24: 0 | C24: 0 | D24: 0 | E24: 0 | F24: 0 | G24: 0 | H24: 0 | I24: 0 | J24: 0 | K24: 0 | L24: 0 | M24: 0 | N24: 0 | O24: 0 | P24: 0 | Q24: 0 | R24: 0 | S24: 0 | T24: 0 | U24: 0 | V24: 0 | W24: 0.006 | X24: 0.019112 | Y24: 0.017049 | Z24: 0.093028 | AA24: 37.559954 | AB24: 43.309938 | AC24: 48.823995 | AD24: 54.545792 | AE24: 63.026424 | AF24: 80.404438 | AG24: 69.023618 | AH24: 66.540608 | AI24: 68.765458 | AJ24: 68.777148 | AK24: 70.720848 | AL24: 27.92118 | AM24: 24.29847 | AN24: 16.48819 | AO24: 88.94066 | AP24: 90.07554 | AQ24: 36.58294 | AR24: 22.48318 | AS24: 15.63438 | AT24: 3.608418 | AU24: 4.050671 | AV24: 3.157 | AW24: 6.123 | AX24: 3.87754 | AY24: 3.936 | AZ24: 3.936 | BA24: 3.936 | BB24: 3.936 | BC24: 3.936 | BD24: 3.936 | BE24: 3.936 | BF24: 3.936 | BG24: 3.936 | BH24: 3.936 | BI24: 3.991313 | BJ24: 22
A25: Cambodia | B25: 0 | C25: 0 | D25: 0 | E25: 0 | F25: 0 | G25: 0 | H25: 0 | I25: 0 | J25: 0 | K25: 0 | L25: 0 | M25: 10 | N25: 17 | O25: 11 | P25: 16 | Q25: 380 | R25: 294 | S25: 298 | T25: 304.49092 | U25: 310.02602 | V25: 314.96283 | W25: 319.9409 | X25: 325.8087 | Y25: 331.66107 | Z25: 337.28793 | AA25: 347.7248 | AB25: 1033.5786 | AC25: 1134.3242 | AD25: 1227.2958 | AE25: 1322.2947 | AF25: 1362.8038 | AG25: 2006.8025 | AH25: 752.0878 | AI25: 849.76772 | AJ25: 927.32 | AK25: 1225.721 | AL25: 883.89 | AM25: 1010.87 | AN25: 1140.3 | AO25: 1265.6 | AP25: 1406.8 | AQ25: 1462.2 | AR25: 1551.4 | AS25: 1608.49 | AT25: 1671.6 | AU25: 1728.8 | AV25: 1787.11 | AW25: 1774.06 | AX25: 1949.3056 | AY25: 1956.0902 | AZ25: 1962.9771 | BA25: 1969.9681 | BB25: 1977.0646 | BC25: 1984.2683 | BD25: 1991.5807 | BE25: 1999.0036 | BF25: 2006.5385 | BG25: 2014.1873 | BH25: 2025 | BI25: 2025 | BJ25: 2025
A26: Cameroon | B26: 0 | C26: 0 | D26: 0 | E26: 0 | F26: 0 | G26: 0 | H26: 0 | I26: 0 | J26: 0 | K26: 0 | L26: 0 | M26: 0 | N26: 0.01218 | O26: 0.051054 | P26: 2.961478 | Q26: 1.611226 | R26: 0 | S26: 1.321999 | T26: 0.868855 | U26: 19.138695 | V26: 16.133273 | W26: 22.181074 | X26: 28.799838 | Y26: 32.798015 | Z26: 36.687589 | AA26: 405.89555 | AB26: 444.03195 | AC26: 510.08135 | AD26: 632.27769 | AE26: 1104.2339 | AF26: 833.86274 | AG26: 1093.2132 | AH26: 1739.4555 | AI26: 1256.6435 | AJ26: 3396.3059 | AK26: 2016.6894 | AL26: 1896.6712 | AM26: 1941.0571 | AN26: 1041.5399 | AO26: 1064.1112 | AP26: 929.32534 | AQ26: 1993.2542 | AR26: 1065.5197 | AS26: 1270.7662 | AT26: 1559.4544 | AU26: 1610.8144 | AV26: 3396.731 | AW26: 332.50391 | AX26: 92.54899 | AY26: 79.51366 | AZ26: 141.58723 | BA26: 0.0030705 | BB26: 64.094443 | BC26: 178.78067 | BD26: 27.128564 | BE26: 2.9906928 | BF26: 288.31222 | BG26: 1082.7111 | BH26: 96.117502 | BI26: 541.52465 | BJ26: 356.3
... A72: Kazakhstan | B72: 0 | C72: 0 | D72: 0 | E72: 0 | F72: 0 | G72: 0 | H72: 0 | I72: 0 | J72: 0 | K72: 0 | L72: 0 | M72: 0 | N72: 0 | O72: 0 | P72: 0 | Q72: 0 | R72: 0 | S72: 0 | T72: 0 | U72: 0 | V72: 0 | W72: 0 | X72: 0 | Y72: 0 | Z72: 0 | AA72: 0 | AB72: 0 | AC72: 0 | AD72: 0 | AE72: 0 | AF72: 0 | AG72: 0 | AH72: 0 | AI72: 21.47 | AJ72: 105.3 | AK72: 161.72 | AL72: 0 | AM72: 0 | AN72: 103.8 | AO72: 388.12 | AP72: 0 | AQ72: 169.72 | AR72: 0 | AS72: 0 | AT72: 0 | AU72: 0 | AV72: 0 | AW72: 0 | AX72: 0 | AY72: 0 | AZ72: 0 | BA72: 0 | BB72: 0 | BC72: 0 | BD72: 1010.427 | BE72: 0.659 | BF72: 515.226 | BG72: 663.007 | BH72: 509.207 | BI72: 428.998 | BJ72: 400
A73: Kenya | B73: 0 | E73: 0 | F73: 0 | G73: 0 | H73: 0 | I73: 0 | J73: 0 | K73: 0 | L73: 0.3 | M73: 0 | N73: 0.011741 | O73: 0.004646 | P73: 0 | Q73: 0.047668 | R73: 0.634124 | S73: 1.142 | T73: 1.713 | U73: 2.284 | V73: 5.664791 | W73: 8.048881 | X73: 9.57393 | Y73: 10.412123 | Z73: 11.030312 | AA73: 14.948662 | AB73: 23.517726 | AC73: 40.851234 | AD73: 65.89867 | AE73: 549.16361 | AF73: 258.1379 | AG73: 361.5482 | AH73: 481.5446 | AI73: 652.4678 | AJ73: 1008.9547 | AK73: 37.47462 | AL73: 24.711428 | AM73: 109.59962 | AN73: 164.08633 | AO73: 246.77752 | AP73: 434.957 | AQ73: 277.3666 | AR73: 183.24529 | AS73: 56.63076 | AT73: 388.95375 | AU73: 268.9352 | AV73: 472.48853 | AW73: 365.20109 | AX73: 337.43834 | AY73: 348.82569 | AZ73: 353.26732 | BA73: 363.70589 | BB73: 341.76997 | BC73: 301.70183 | BD73: 252.79442 | BE73: 237.60925 | BF73: 259.20428 | BG73: 299.69587 | BH73: 359.3842 | BI73: 256.82972 | BJ73: 880.8
A74: Korea (North) | B74: 0 | C74: 0 | D74: 0 | E74: 0 | F74: 0 | G74: 0 | H74: 0 | I74: 0 | J74: 0 | K74: 0 | L74: 0 | M74: 0 | N74: 0 | O74: 0 | P74: 0 | Q74: #N/A | R74: #N/A | S74: #N/A | T74: #N/A | U74: #N/A | V74: #N/A | W74: #N/A | X74: #N/A | Y74: #N/A | Z74: 417.10788 | AA74: 552.1582 | AB74: 747.66522 | AC74: 983.29535 | AD74: 926.03136 | AE74: 973.92146 | AF74: 1251.112 | AG74: 1312.8426 | AH74: 1644.4931 | AI74: 1467.5657 | AJ74: 1756.039 | AK74: 2077.3632 | AL74: 1972.9276 | AM74: 1837.3214 | AN74: 1935.4211 | AO74: 1836.3081 | AP74: 1822.4738 | AQ74: 1848.4058 | AR74: 2313.6445 | AS74: 2815.1907 | AT74: 3135.7716 | AU74: 2821.6649 | AV74: 3208.6091 | AW74: 3662.2702 | AX74: 13380.969 | AY74: 13980.437 | AZ74: 14022.439 | BA74: 14302.248 | BB74: 24704.013 | BC74: 15225.021 | BD74: 6843.5083 | BE74: 6482.937 | BF74: 6197.9119 | BG74: 6548.0749 | BH74: 6194.6631 | BI74: 5988.6175 | BJ74: 6380.383
A75: Kyrgyz Republic | AG75: 0 | AH75: 0 | AI75: 0.900304 | AJ75: 24.42291 | AK75: 21.7476 | AL75: 91.70198 | AM75: 1.114485 | AN75: 0 | AO75: 32.02811 | AP75: 60.91209 | AQ75: 66.863476 | AR75: 104.37675 | AS75: 45.036381 | AT75: 48.753549 | AU75: 555.89906 | AV75: 11.117075 | AW75: 22.43666 | AX75: 16.71572 | AY75: 17.27339 | AZ75: 18.256785 | BA75: 9.7947747 | BB75: 61.427703 | BC75: 199.32678 | BD75: 18.223082 | BE75: 0.0554292 | BF75: 44.994244 | BG75: 30.056965 | BH75: 240 | BI75: 0 | BJ75: 0
A76: Laos | B76: 0 | C76: 0 | D76: 0 | E76: 0 | F76: 0 | G76: 0 | H76: 0 | I76: 0 | J76: 0 | K76: 0 | L76: 0 | M76: 0 | N76: 0.225 | O76: 0.273 | P76: 0.128 | Q76: 0.608789 | R76: 156.11762 | S76: 1.800955 | T76: 3.186875 | U76: 4.261803 | V76: 5.508845 | W76: 5.300848 | X76: 5.24652 | Y76: 4.867941 | Z76: 4.777536 | AA76: 6.752095 | AB76: 8.766914 | AC76: 12.713977 | AD76: 0.668 | AE76: 0.254 | AF76: 1.021 | AG76: 1291.919 | AH76: 0.4 | AI76: 0 | AJ76: 0 | AK76: 0 | AL76: 1.584 | AM76: 1.659 | AN76: 0.696 | AO76: 0.984 | AP76: 1.22 | AQ76: 0.017 | AR76: 0 | AS76: 905 | AT76: 0 | AU76: 0 | AV76: 45 | AW76: 0 | AX76: 0 | AY76: 0 | AZ76: 0 | BA76: 0 | BB76: 0.0026388 | BC76: 0.0027582 | BD76: 0.0024282 | BE76: 0.0021774 | BF76: 0.0021082 | BG76: 0.0023986 | BH76: 0.00229 | BI76: 0.002468 | BJ76: 0
A77: Lebanon | B77: 0 | C77: 0 | D77: 0 | E77: 0 | F77: 0 | G77: 0 | H77: 0 | I77: 0 | J77: 0 | K77: 0 | L77: 0 | M77: 0 | N77: 0 | O77: 0 | P77: 0 | Q77: 0 | R77: 0.3 | S77: 0 | T77: 0 | U77: 0 | V77: 0 | W77: 0 | X77: 8.265 | Y77: 17.933 | Z77: 27.551 | AA77: 37.084 | AB77: 47.129 | AC77: 64.254 | AD77: 96.244 | AE77: 130.399 | AF77: 171.307 | AG77: 183.431 | AH77: 77.798 | AI77: 71.976 | AJ77: 59.595 | AK77: 51.299 | AL77: 0 | AM77: 0 | AN77: 0 | AO77: 0 | AP77: 0 | AQ77: 0 | AR77: 0.125 | AS77: 0 | AT77: 0 | AU77: 0 | AV77: 0 | AW77: 0 | AX77: 0 | AY77: 0 | AZ77: 0 | BA77: 0 | BB77: 0 | BC77: 0 | BD77: 0 | BE77: 0 | BF77: 0 | BG77: 0 | BH77: 0 | BI77: 0 | BJ77: 37502.042
A78: Lesotho | H78: 0 | I78: 0 | J78: 0 | K78: 0 | L78: 0 | M78: 0 | N78: 0 | O78: 0 | P78: 0 | Q78: 0 | R78: 0 | S78: 0 | T78: 0 | U78: 0.000578 | V78: 0 | W78: 0 | X78: 0 | Y78: 0 | Z78: 0 | AA78: 0.195758 | AB78: 0.043939 | AC78: 0.037663 | AD78: 0.04057 | AE78: 0.033 | AF78: 8.121312 | AG78: 3.69621 | AH78: 5.575755 | AI78: 12.051992 | AJ78: 2.884411 | AK78: 0 | AL78: 0 | AM78: 0 | AN78: 0.063361 | AO78: 0 | AP78: 0 | AQ78: 4.6 | AR78: 0 | AS78: 0 | AT78: 0 | AU78: 0 | AV78: 0 | AW78: 5.850245 | AX78: 1.439697 | AY78: 0.001568 | AZ78: 0.0702472 | BA78: 0.216046 | BB78: 0.1299833 | BC78: 0.0702472 | BD78: 0.216046 | BE78: 0.1321607 | BF78: 0.3750295 | BG78: 0.1768764 | BH78: 12.133888 | BI78: 0.30163 | BJ78: 0
A79: Liberia | B79: 0 | C79: 0 | D79: 0 | E79: 122 | F79: 0 | G79: 0 | H79: 0 | I79: 0 | J79: 112 | K79: 5 | L79: 0 | M79: 0.078 | N79: 0.077 | O79: 0.134 | P79: 0.241 | Q79: 0.047 | R79: 0.054 | S79: 0.126 | T79: 1.275 | U79: 1.798 | V79: 37.3 | W79: 43.9 | X79: 60.647 | Y79: 71.3 | Z79: 113.25 | AA79: 469.55434 | AB79: 838.9215 | AC79: 1004.325 | AD79: 1047.7022 | AE79: 1117.7455 | AF79: 1241.1085 | AG79: 1333.853 | AH79: 1390.9026 | AI79: 1459.3808 | AJ79: 1575.8633 | AK79: 1707.5553 | AL79: 1762.9759 | AM79: 1796.9398 | AN79: 1946.006 | AO79: 2015.9386 | AP79: 2147.3597 | AQ79: 2188.8416 | AR79: 2412.6567 | AS79: 2663.7163 | AT79: 2520.4081 | AU79: 2875.8517 | AV79: 3062.6504 | AW79: 3291.556 | AX79: 4066.3197 | AY79: 3061.032 | AZ79: 2948.2398 | BA79: 110.38598 | BB79: 121.04194 | BC79: 92.0248 | BD79: 78.614835 | BE79: 78.596 | BF79: 78.596 | BG79: 78.596 | BH79: 78.596 | BI79: 78.652696 | BJ79: 78.652696
A80: Libya | B80: 0 | C80: 0 | D80: 0 | E80: 0 | F80: 0 | G80: 0 | H80: 0 | I80: 0 | J80: 0 | K80: 0 | L80: 0 | M80: 0 | N80: 0 | O80: 0 | P80: 0 | Q80: 0 | R80: 0 | S80: 0 | T80: 0 | U80: 0 | V80: 0 | W80: 0 | X80: 0 | Y80: 0 | Z80: 0 | AA80: 0 | AB80: 0 | AC80: 0 | AD80: 0 | AE80: 0 | AF80: 0 | AG80: 0 | AH80: 0 | AI80: 0 | AJ80: 0 | AK80: 0 | AL80: 0 | AM80: 0 | AN80: 0 | AO80: 0 | AP80: 0 | AQ80: 0 | AR80: 0 | AS80: 0 | AT80: 441 | AU80: 0 | AV80: 0 | AW80: 0 | AX80: 4500 | AY80: 0 | AZ80: 0 | BA80: 3200 | BB80: 3200 | BC80: 3200 | BD80: 3200 | BE80: 3200 | BF80: 3200 | BG80: 3200 | BH80: 3200 | BI80: 3200 | BJ80: 3200
